Workbook
Name AAA: #REF!
Name aaaa: #REF!
Name aaaa: #REF!
Name aaaaa: #REF!
Name aaaaa: #REF!
Name aaaaaaa: #REF!
Name asd: #REF!
Name asd: #REF!
Name asd: #REF!
Name asd: #REF!
Name BTSCOV_DU: [2]Assumption!$J$34
Name BTSCOV_DU: [3]Assumption!$J$34
Name BTSCOV_SU: [2]Assumption!$J$36
Name BTSCOV_SU: [3]Assumption!$J$36
Name BTSCOV_U: [2]Assumption!$J$35
Name BTSCOV_U: [3]Assumption!$J$35
Name CEK: #REF!
Name CEK: #REF!
Name Cells: #REF!
Name Cells: #REF!
Name Cells: #REF!
Name Cells: #REF!
Name Cells: #REF!
Name Cells: #REF!
Name DENSITY_DU: [2]Assumption!$F$34
Name DENSITY_DU: [3]Assumption!$F$34
Name DENSITY_SU: [2]Assumption!$F$36
Name DENSITY_SU: [3]Assumption!$F$36
Name DENSITY_U: [2]Assumption!$F$35
Name DENSITY_U: [3]Assumption!$F$35
Name dfaereqar: #REF!
Name dfaereqar: #REF!
Name dfaereqar: #REF!
Name dfsfaef: #REF!
Name dfsfaef: #REF!
Name dqf: [2]Assumption!$F$36
Name dvzvgd: #REF!
Name eq: #REF!
Name eq: #REF!
Name Excel_BuiltIn_Print_Titles_1_1: #REF!
Name Excel_BuiltIn_Print_Titles_1_1: #REF!
Name Excel_BuiltIn_Print_Titles_1_1: #REF!
Name Excel_BuiltIn_Print_Titles_1_1: #REF!
Name Excel_BuiltIn_Print_Titles_1_1: #REF!
Name f: #REF!
Name faefaefaef: #REF!
Name faefqaefrqeqefr: #REF!
Name General: #REF!
Name General: #REF!
Name General: #REF!
Name General: #REF!
Name ggggg: #REF!
Name gggggg: [2]Assumption!$D$30
Name Joint1: #REF!
Name Joint1: #REF!
Name Joint1: #REF!
Name Joint2: #REF!
Name Joint2: #REF!
Name Joint3: #REF!
Name Joint3: #REF!

Sheet Cover Isat (FLP) 
B10: PT. IFORTE SOLUSI INFOTEK
B11: OPTICAL SITE PLANT | BB11: =L22 -> IF-PCN-FiberImprovement-DF162
B12: ACCEPTANCE TEST DOCUMENT | BB12: =L23 -> 16PCN0025 - 16PCN0023
A13: VERSION 5.1 | BB13: =L24 -> 16PCN0025
BB14: =L25 -> PURWOREJO_PCN_ST
BB16: =L27 -> 16PCN0023
BB17: =L28 -> NGELEBENGAN_TB
B19: Customer Name | K19: : | L19: PT. Indosat Ooredoo Hutchison | BB19: =CONCATENATE("(",L25," - ",L28,")") -> (PURWOREJO_PCN_ST - NGELEBENGAN_TB)
B20: SCOPE | K20: : | L20: New Ring | AE20: New Ring / Existing Insert / Insert Site / Relocation Site
B21: EXISTING SPAN | K21: : | L21: -
B22: Ring ID | K22: : | L22: IF-PCN-FiberImprovement-DF162
B23: Span ID | K23: : | L23: =CONCATENATE(L24," - ",L27) -> 16PCN0025 - 16PCN0023
B24: Site ID A | K24: : | L24: 16PCN0025
B25: Site Name A | K25: : | L25: PURWOREJO_PCN_ST
B26: Coordinat A | K26: : | L26: Lat : | M26: -8.193392 S | T26: Long : | V26: 111.129138 E
B27: Site ID B | K27: : | L27: 16PCN0023
B28: Site Name B | K28: : | L28: NGELEBENGAN_TB
B29: Coordinat B | K29: : | L29: Lat : | M29: -8.196840 S | T29: Long : | V29: 111.121630 E
B30: FO Length | K30: : | L30: 1.498 M
B31: NEW CABLE LENGTH | K31: : | L31: -
B32: Total Core | K32: : | L32: 2 Core
B33: Date of Submit Acceptance | K33: : | L33: -
B34: Date of Accepted | K34: :
B35: Acceptance Status | K35: : | L35: X | M35: Pass, no pending items
M37: Pass, with pending items
M39: Rejected
C52: PT. Indosat | S52: Vendor Name

Sheet Test Result Core (FLP) 
O2: NPMQ_only
B6: A. Site Information
B7: Span ID | E7: ='Cover Isat (FLP) '!L23 -> 16PCN0025 - 16PCN0023
B8: Site A | E8: Site ID | H8: ='Cover Isat (FLP) '!L24 -> 16PCN0025 | Q8: Site Name | T8: ='Cover Isat (FLP) '!L25 -> PURWOREJO_PCN_ST
E9: Latitude | H9: ='Cover Isat (FLP) '!M26 -> -8.193392 S | Q9: Longitude | T9: ='Cover Isat (FLP) '!V26 -> 111.129138 E
B10: Site B | E10: Site ID | H10: ='Cover Isat (FLP) '!L27 -> 16PCN0023 | Q10: Site Name | T10: ='Cover Isat (FLP) '!L28 -> NGELEBENGAN_TB
E11: Latitude | H11: ='Cover Isat (FLP) '!M29 -> -8.196840 S | Q11: Longitude | T11: ='Cover Isat (FLP) '!V29 -> 111.121630 E
B12: Test Date | E12: ='Cover Isat (FLP) '!L33 -> -
B13: Total Core | E13: ='Cover Isat (FLP) '!L32 -> 2 Core
B15: B. Visual Check
B16: No. | D16: Description | Q16: Results
B18: 1. | D18: OTB installation | R18: X | S18: OK | V18: Not OK
B20: 2. | D20: Indoor FO cable installation | R20: X | S20: OK | V20: Not OK
B22: 3. | D22: Labelling | R22: X | S22: OK | V22: Not OK
B24: 4. | D24: Outdoor FO cable installation | R24: X | S24: OK | V24: Not OK
B27: C.1. OTDR Results
B28: Reference Attenuation : | H28: 0.33 | I28: dB/km
C29: *Vendor should fill in value of reference attenuation base on type of cable (existing/new)
B31: Lambda | E31: Fiber No. | H31: Optical Length (km) | L31: Att. A-B (dB/km) | O31: Status A-B | P31: Att. B-A (dB/km) | S31: Status B-A | U31: Overall Status
B32: 1550 nm | E32: 1 | H32: =1.498 -> 1.498 | L32: 0.164 | O32: =IF(L32<=$H$28,"PASS","FAILED") -> PASS | P32: 0.17 | S32: =IF(P32<=$H$28,"PASS","FAILED") -> PASS | U32: =IF(AND(S32="PASS",O32="PASS"),"PASS","FAILED") -> PASS
E33: 2 | H33: =H32 -> 1.498 | L33: 0.161 | O33: =IF(L33<=$H$28,"PASS","FAILED") -> PASS | P33: 0.167 | S33: =IF(P33<=$H$28,"PASS","FAILED") -> PASS | U33: =IF(AND(S33="PASS",O33="PASS"),"PASS","FAILED") -> PASS
E34: 3 | O34: =IF(L34<=$H$28,"PASS","FAILED") -> PASS | S34: =IF(P34<=$H$28,"PASS","FAILED") -> PASS | U34: =IF(AND(S34="PASS",O34="PASS"),"PASS","FAILED") -> PASS
E35: 5 | O35: =IF(L35<=$H$28,"PASS","FAILED") -> PASS | S35: =IF(P35<=$H$28,"PASS","FAILED") -> PASS | U35: =IF(AND(S35="PASS",O35="PASS"),"PASS","FAILED") -> PASS
E36: 6 | O36: =IF(L36<=$H$28,"PASS","FAILED") -> PASS | S36: =IF(P36<=$H$28,"PASS","FAILED") -> PASS | U36: =IF(AND(S36="PASS",O36="PASS"),"PASS","FAILED") -> PASS
E37: 7 | O37: =IF(L37<=$H$28,"PASS","FAILED") -> PASS | S37: =IF(P37<=$H$28,"PASS","FAILED") -> PASS | U37: =IF(AND(S37="PASS",O37="PASS"),"PASS","FAILED") -> PASS
E38: 8 | O38: =IF(L38<=$H$28,"PASS","FAILED") -> PASS | S38: =IF(P38<=$H$28,"PASS","FAILED") -> PASS | U38: =IF(AND(S38="PASS",O38="PASS"),"PASS","FAILED") -> PASS
E39: 9 | O39: =IF(L39<=$H$28,"PASS","FAILED") -> PASS | S39: =IF(P39<=$H$28,"PASS","FAILED") -> PASS | U39: =IF(AND(S39="PASS",O39="PASS"),"PASS","FAILED") -> PASS
E40: 10 | O40: =IF(L40<=$H$28,"PASS","FAILED") -> PASS | S40: =IF(P40<=$H$28,"PASS","FAILED") -> PASS | U40: =IF(AND(S40="PASS",O40="PASS"),"PASS","FAILED") -> PASS
E41: 11 | O41: =IF(L41<=$H$28,"PASS","FAILED") -> PASS | S41: =IF(P41<=$H$28,"PASS","FAILED") -> PASS | U41: =IF(AND(S41="PASS",O41="PASS"),"PASS","FAILED") -> PASS
E42: 12 | O42: =IF(L42<=$H$28,"PASS","FAILED") -> PASS | S42: =IF(P42<=$H$28,"PASS","FAILED") -> PASS | U42: =IF(AND(S42="PASS",O42="PASS"),"PASS","FAILED") -> PASS
E43: 13 | O43: =IF(L43<=$H$28,"PASS","FAILED") -> PASS | S43: =IF(P43<=$H$28,"PASS","FAILED") -> PASS | U43: =IF(AND(S43="PASS",O43="PASS"),"PASS","FAILED") -> PASS
E44: 14 | O44: =IF(L44<=$H$28,"PASS","FAILED") -> PASS | S44: =IF(P44<=$H$28,"PASS","FAILED") -> PASS | U44: =IF(AND(S44="PASS",O44="PASS"),"PASS","FAILED") -> PASS
E45: 15 | O45: =IF(L45<=$H$28,"PASS","FAILED") -> PASS | S45: =IF(P45<=$H$28,"PASS","FAILED") -> PASS | U45: =IF(AND(S45="PASS",O45="PASS"),"PASS","FAILED") -> PASS
B47: C.2. Power Meter Result (Link LOS)
B48: Power Meter Calibration | H48: EQUIPMENT CALIBRATION
H49: First (dB) | J49: Second (dB) | N49: Third (dB) | Q49: Average (dB)
H50: -7.28 | J50: -7.05 | N50: -7.19 | Q50: =AVERAGE(H50:P50) -> -7.1733333
B52: Reference Link LOS | G52: = | H52: =(AVERAGE(H32:K35)*0.22)+(V53*0.15)+(V52*0.25) -> 1.12956 | I52: dB | P52: Number Connector | U52: : | V52: 2
P53: Number Splicing | U53: : | V53: 2
P54: * Vendor should fill in value of number of splicing
...

Sheet OTDR
A1: NEAR END /FAR END | B1: SITE ID | C1: SITE NAME | D1: ODP/OTB | E1: OTDR PHOTO & SURROUNDING | H1: OTDR PHOTO | K1: OTDR PHOTO & SURROUNDING | N1: OTDR PHOTO | Q1: OTDR PHOTO & SURROUNDING | T1: OTDR PHOTO | W1: OTDR PHOTO & SURROUNDING | Z1: OTDR PHOTO | AC1: OTDR PHOTO & SURROUNDING | AF1: OTDR PHOTO | AI1: OTDR PHOTO & SURROUNDING | AL1: OTDR PHOTO | AO1: OTDR PHOTO & SURROUNDING | AR1: OTDR PHOTO | AU1: OTDR PHOTO & SURROUNDING | AX1: OTDR PHOTO | BA1: OTDR PHOTO & SURROUNDING | BD1: OTDR PHOTO | BG1: OTDR PHOTO & SURROUNDING | BJ1: OTDR PHOTO | BM1: OTDR PHOTO & SURROUNDING | BP1: OTDR PHOTO | BS1: OTDR PHOTO & SURROUNDING | BV1: OTDR PHOTO | BY1: OTDR PHOTO & SURROUNDING | CB1: OTDR PHOTO | CE1: OTDR PHOTO & SURROUNDING | CH1: OTDR PHOTO
A2: NEAR END | B2: ='Cover Isat (FLP) '!$BB$13 -> 16PCN0025 | C2: ='Cover Isat (FLP) '!$BB$14 -> PURWOREJO_PCN_ST | D2: ODP ACPDB | E2: Foto pengukuran dengan OTDR dan perangkat sekitarnya : - Foto OTDR saat berada di dekat OTB / ODP - Foto harus disertai Geotagging | H2: Foto hasil pengukuran dengan OTDR : - Foto OTDR harus jelas dan nilai harus terbaca - Foto harus disertai Geotagging | AC2: Foto pengukuran dengan OTDR dan perangkat sekitarnya : - Foto OTDR saat berada di dekat OTB / ODP - Foto harus disertai Geotagging | AF2: Foto hasil pengukuran dengan OTDR : - Foto OTDR harus jelas dan nilai harus terbaca - Foto harus disertai Geotagging | BA2: Foto pengukuran dengan OTDR dan perangkat sekitarnya : - Foto OTDR saat berada di dekat OTB / ODP - Foto harus disertai Geotagging | BD2: Foto hasil pengukuran dengan OTDR : - Foto OTDR harus jelas dan nilai harus terbaca - Foto harus disertai Geotagging | BY2: Foto pengukuran dengan OTDR dan perangkat sekitarnya : - Foto OTDR saat berada di dekat OTB / ODP - Foto harus disertai Geotagging | CB2: Foto hasil pengukuran dengan OTDR : - Foto OTDR harus jelas dan nilai harus terbaca - Foto harus disertai Geotagging
E16: CORE 1 | K16: CORE 2 | Q16: CORE 3 | W16: CORE 4 | AC16: CORE 5 | AI16: CORE 6 | AO16: CORE 7 | AU16: CORE 8 | BA16: CORE 9 | BG16: CORE 10 | BM16: CORE 11 | BS16: CORE 12 | BY16: CORE 13 | CE16: CORE 14
A17: FAR END | B17: ='Cover Isat (FLP) '!$BB$16 -> 16PCN0023 | C17: ='Cover Isat (FLP) '!$BB$17 -> NGELEBENGAN_TB | D17: ODP ACPDB | E17: Foto pengukuran dengan OTDR dan perangkat sekitarnya : - Foto OTDR saat berada di dekat OTB / ODP - Foto harus disertai Geotagging | H17: Foto hasil pengukuran dengan OTDR : - Foto OTDR harus jelas dan nilai harus terbaca - Foto harus disertai Geotagging | AC17: Foto pengukuran dengan OTDR dan perangkat sekitarnya : - Foto OTDR saat berada di dekat OTB / ODP - Foto harus disertai Geotagging | AF17: Foto hasil pengukuran dengan OTDR : - Foto OTDR harus jelas dan nilai harus terbaca - Foto harus disertai Geotagging | BA17: Foto pengukuran dengan OTDR dan perangkat sekitarnya : - Foto OTDR saat berada di dekat OTB / ODP - Foto harus disertai Geotagging | BD17: Foto hasil pengukuran dengan OTDR : - Foto OTDR harus jelas dan nilai harus terbaca - Foto harus disertai Geotagging | BY17: Foto pengukuran dengan OTDR dan perangkat sekitarnya : - Foto OTDR saat berada di dekat OTB / ODP - Foto harus disertai Geotagging | CB17: Foto hasil pengukuran dengan OTDR : - Foto OTDR harus jelas dan nilai harus terbaca - Foto harus disertai Geotagging
E31: CORE 1 | K31: CORE 2 | Q31: CORE 3 | W31: CORE 4 | AC31: CORE 5 | AI31: CORE 6 | AO31: CORE 7 | AU31: CORE 8 | BA31: CORE 9 | BG31: CORE 10 | BM31: CORE 11 | BS31: CORE 12 | BY31: CORE 13 | CE31: CORE 14
A32: Insert Span (*if any) | D32: New Cable | H32: Foto pengukuran dengan OTDR untuk site Insert dari site ke Joint Closure : - Pengukuran dilakukan pada saat Cut Over - Foto OTDR terlihat jelas panjang new cable - Foto harus disertai Geotagging | K32: #VALUE! | N32: Foto pengukuran dengan OTDR untuk site Insert dari site ke Joint Closure : - Pengukuran dilakukan pada saat Cut Over - Foto OTDR terlihat jelas panjang new cable - Foto harus disertai Geotagging | T32: Foto pengukuran dengan OTDR untuk site Insert dari site ke Joint Closure : - Pengukuran dilakukan pada saat Cut Over - Foto OTDR terlihat jelas panjang new cable - Foto harus disertai Geotagging | W32: #VALUE! | Z32: Foto pengukuran dengan OTDR untuk site Insert dari site ke Joint Closure : - Pengukuran dilakukan pada saat Cut Over - Foto OTDR terlihat jelas panjang new cable - Foto harus disertai Geotagging
E46: CORE 1 | K46: CORE 2 | Q46: CORE 7 | W46: CORE 8
E47: Foto pengukuran dengan OTDR untuk site Insert dari site ke Joint Closure : - Pengukuran dilakukan pada saat Cut Over - Foto OTDR terlihat jelas panjang new cable - Foto harus disertai Geotagging | K47: Foto pengukuran dengan OTDR untuk site Insert dari site ke Joint Closure : - Pengukuran dilakukan pada saat Cut Over - Foto OTDR terlihat jelas panjang new cable - Foto harus disertai Geotagging

Sheet OPM
A1: Photo Kalibrasi OPM
A3: SITE ID | B3: NAME SITE | C3: FOTO KEGIATAN | D3: FOTO KEGIATAN | E3: FOTO KEGIATAN | F3: FOTO KEGIATAN | G3: FOTO KEGIATAN | H3: FOTO KEGIATAN | I3: FOTO KEGIATAN | J3: FOTO KEGIATAN | K3: FOTO KEGIATAN | L3: FOTO KEGIATAN | M3: FOTO KEGIATAN | N3: FOTO KEGIATAN | O3: FOTO KEGIATAN | P3: FOTO KEGIATAN
A4: =OTDR!B2 -> 16PCN0025 | B4: =OTDR!C2 -> PURWOREJO_PCN_ST
C5: CORE 5 | D5: CORE 6 | E5: CORE 3 | F5: CORE 4 | G5: CORE 5 | H5: CORE 6 | I5: CORE 7 | J5: CORE 8 | K5: CORE 9 | L5: CORE 10 | M5: CORE 11 | N5: CORE 12 | O5: CORE 13 | P5: CORE 14
A6: =OTDR!B17 -> 16PCN0023 | B6: =OTDR!C17 -> NGELEBENGAN_TB
C7: CORE 7 | D7: CORE 8 | E7: CORE 3 | F7: CORE 4 | G7: CORE 5 | H7: CORE 6 | I7: CORE 7 | J7: CORE 8 | K7: CORE 9 | L7: CORE 10 | M7: CORE 11 | N7: CORE 12 | O7: CORE 13 | P7: CORE 14

Sheet OTB, ODP & LABELLING
A1: NEAR END /FAR END | B1: SITE ID | C1: SITE NAME | D1: TERMINATION TYPE | E1: ODP / OTB PHOTO | H1: LABEL ODP / OTB (Patchcord/port) | K1: LABEL Patchcord from ODP on Metro-E (*if applicable)
A2: NEAR END | B2: =OTDR!B2 -> 16PCN0025 | C2: =OTDR!C2 -> PURWOREJO_PCN_ST | D2: =OTDR!D2 -> ODP ACPDB
E16: OTB (Jika didalam rak): - Foto instalasi pada OTB harus terlihat jelas dan rapih - Foto memperlihatkan OTB terpasang pada Cabinet - Foto harus disertai Geotagging ODP (Jika diluar rak / di bawah acpdb) : - Foto instalasi pada ODP terlihat jelas dan rapih - Foto memperlihatkan ODP terpasang di tiang/pole - Foto harus disertai Geotagging | H16: Foto Label pada OTB / ODP : - Apabila ODP maka stiker label ditempel pada kabel & port harus terlihat dan terbaca jelas - Apabila OTB maka stiker label ditempel pada port harus terbaca dan terlihat jelas - Material label harus waterprof - Foto harus disertai Geotagging | K16: Foto Label pada Patchcore disisi Metro-E : - Apabila terminasi dari ODP langsung ke ME tanpa OTB - Stiker label ditempel pada kedua ujung kabel disisi ME dan sisi ODP harus terbaca dan terlihat jelas - Material label harus waterprof - Foto harus disertai Geotagging - Foto patchord outdoor dengan conduit harus terlihat jelas
H22: Format label sbb : | K22: Format label sbb :
H23: INDOSAT OPTICAL | K23: INDOSAT OPTICAL
H24: SITEIDNE_PORT#1_to_SITEIDFE_PORT#1 | K24: SITEIDNE_PORT#1_to_SITEIDFE_PORT#1
A25: FAR END | B25: =OTDR!B17 -> 16PCN0023 | C25: =OTDR!C17 -> NGELEBENGAN_TB | D25: =OTDR!D17 -> ODP ACPDB
K40: Foto Label pada Patchcore disisi Metro-E : - Apabila terminasi dari ODP langsung ke ME tanpa OTB - Stiker label ditempel pada kedua ujung kabel disisi ME dan sisi ODP harus terbaca dan terlihat jelas - Material label harus waterprof - Foto harus disertai Geotagging - Foto patchord outdoor dengan conduit harus terlihat jelas
E41: OTB (Jika didalam rak): - Foto instalasi pada OTB harus terlihat jelas dan rapih - Foto memperlihatkan OTB terpasang pada Cabinet - Foto harus disertai Geotagging ODP (Jika diluar rak / di bawah acpdb) : - Foto instalasi pada ODP terlihat jelas dan rapih - Foto memperlihatkan ODP terpasang di tiang/pole - Foto harus disertai Geotagging | H41: Foto Label pada OTB / ODP : - Apabila ODP maka stiker label ditempel pada kabel & port harus terlihat dan terbaca jelas - Apabila OTB maka stiker label ditempel pada port harus terbaca dan terlihat jelas - Material label harus waterprof - Foto harus disertai Geotagging
H47: Format label sbb : | K47: Format label sbb :
H48: INDOSAT OPTICAL | K48: INDOSAT OPTICAL
H49: SITEIDNE_PORT#1_to_SITEIDFE_PORT#1 | K49: SITEIDNE_PORT#1_to_SITEIDFE_PORT#1
A51: Insert Site (*if any) | D51: Termination Insert
E67: Foto menunjukan lokasi terminasi insert cable - Apabila koneksi di ODP maka foto ODP terlihat jelas dan rapih - Foto memperlihatkan ODP terpasang di tiang/pole - Foto harus disertai Geotagging

Sheet Cable Route In
B2: NEAR END
B4: Kabel FO masuk melalui tiang KWH | G4: Kabel FO menggunakan conduit ditanam menuju Rack OTB
B16: Route kabel mengikuti tray horizontal | G16: Route kabel tanam menuju Rack OTB
B28: FAR END
B30: Kabel FO masuk melalui tiang KWH | G30: Kabel FO menggunakan conduit ditanam menuju Rack OTB
B42: Route kabel mengikuti tray horizontal | G42: Route kabel tanam menuju Rack OTB

Sheet Cable Route Out
B2: NEAR END
B4: Slack
B16: Closure
B27: TIANG
B50: FAR END
B52: Slack
B64: Closure
B75: Tiang

Sheet KMZ
A1: AS BUILT DRAWING
A2: Span End to End
A34: New cable Insert (*if any)

Sheet Lay Out ABD (NE & FE)
B5: NEAR END (for New Span)
B6: SITE NAME : | H6: ='Cover Isat (FLP) '!$BB$14 -> PURWOREJO_PCN_ST
B7: SITE ID : | H7: ='Cover Isat (FLP) '!$BB$13 -> 16PCN0025
C46: Site Id | D46: Site Name | E46: File PDF
C47: =H7 -> 16PCN0025 | D47: =H6 -> PURWOREJO_PCN_ST
B50: FAR END (for New Span)
B51: LAYOUT
B52: SITE NAME : | H52: ='Cover Isat (FLP) '!$BB$17 -> NGELEBENGAN_TB
B53: SITE ID : | H53: ='Cover Isat (FLP) '!$BB$16 -> 16PCN0023
C92: Site Id | D92: Site Name | E92: File PDF
C93: =H53 -> 16PCN0023 | D93: =H52 -> NGELEBENGAN_TB
B98: NEAR END Only (for Site Insert)
B99: SITE NAME :
B100: SITE ID :
C139: Site Id | D139: Site Name | E139: File PDF

Sheet FLP Schematic Core
B2: CONECTION CORE TO CORE
B3: SPAN ID : | K3: ='Cover Isat (FLP) '!BB12 -> 16PCN0025 - 16PCN0023
B7: SYNOPTIC CABLE
B8: ='Cover Isat (FLP) '!$BB$11 -> IF-PCN-FiberImprovement-DF162
B9: ='Cover Isat (FLP) '!BB19 -> (PURWOREJO_PCN_ST - NGELEBENGAN_TB)
D12: ='Cover Isat (FLP) '!BB13 -> 16PCN0025 | M12: ='Cover Isat (FLP) '!BB16 -> 16PCN0023
B13: ='Cover Isat (FLP) '!BB14 -> PURWOREJO_PCN_ST | K13: ='Cover Isat (FLP) '!BB17 -> NGELEBENGAN_TB
B15: =OTDR!D2 -> ODP ACPDB | R15: =OTDR!D17 -> ODP ACPDB

Sheet Sheet1

Sheet Change Log Version
A1: No | B1: Version | C1: Revision date | D1: Change Log | E1: Author
A2: 1 | B2: Version : 3.0 | C2: 44090 | D2: Initial template : Sheet - Test Result Core (SPAN-MMP) - Test OTDR (RING) - Test OTDR (SPAN-MMP) - Test OPM (RING) - Test OPM (SPAN-MMP) - OTDR - OPM - OTB, ODP & LABELLING - KMZ - Lay Out ABD - Schematic Core | E2: IOH
A3: 2 | B3: Version : 4.0 | C3: 44280 | D3: Remove Sheet : - Test OTDR (RING) - Test OPM (RING) | E3: IOH
A4: 3 | B4: Version : 4.2 | C4: 44354 | D4: Remove Sheet : - Test OTDR (SPAN) - Test OPM (SPAN) - TLP (MMP) Schematic Core | E4: IOH
A5: 4 | B5: Version : 5.0 | C5: 45309 | D5: Add : Sheet Change Log Version Sheet Test Result Core - OTDR Result Core 5 - 14 - OPM Result Core 5 - 14 Sheet OTDR - OTDR Photo Core 5 - 14 Sheet OPM - OPM Photo Core 5 - 14 | E5: IOH
A6: 5 | B6: Version : 5.1 | D6: Add : Sheet OTDR - Penambahan pengukuran OTDR New Cable Core 1,2 & 7,8 untuk scope Insert Site (*if Any) Sheet Cable Route In Photo Near End & Far End : - Kabel FO masuk melalui tiang KWH - Kabel FO menggunakan conduit ditanam menuju Rack OTB - Route kabel mengikuti tray horizontal - Route kabel tanam menuju Rack OTB Sheet Cable Route Out Photo Near End & Far End : - Photo Slack - Photo Closure - Photo Tiang Sheet Lay Out ABD - Lay Out ABD Near End & Far End (for New Span Only); or - Lay Out ABD Near End (for Site Insert Only) Sheet KMZ - Capture distance KMZ on google earth - Penambahan capture KMZ untuk span existing dan site insert serta menampilkan jarak KMZ New cable. (*if Any) | E6: IOH
