Workbook

Sheet Summary PO Permit
A1: Summary PO RT/RW (CLUSTER NAME)
A2: Permit | B2: 7650000
A3: (Permit + PPh 2.65%) | B3: =B2+(B2*2.65%) -> 7852725

Sheet BoQ NRO Cluster
A1: DISTRIBUSI - SUBFEEEDER | N1: AS PLAN
A2: BOQ GPON FTTH FOR OPTICAL DISTRIBUTION NETWORK (ODN) | N2: OLT Name
A3: PT. EKA MAS REPUBLIK ODN, OSP, Aktivasi, Instalasi, Integrasi, Testing & Dokumentasi | N3: Cluster | O3: APD - RANCA PANGGUNG RW 08
A4: PROJECT ROLL OUT 2024 | N4: Net Type | O4: Aerial
N5: HP | O5: 118
A6: No | B6: Description/Item | C6: Unit | D6: Material Qty | E6: Service Qty | F6: Material Price | G6: Service Price | H6: Total Material Price | I6: Total Service Price | J6: Total Price | M6: Koreksi No Material | N6: No Material | O6: Short Text/Description SAP | P6: Remarks | Q6: Service
A7: 1 | B7: Pengamanan & Persiapan
A8: 1.1 | B8: Pengamanan Perizinan dan K3 | C8: ls | E8: 1 | L8: =F8+G8 -> 0 | N8: 500004774 | O8: PENGAMANAN PERIZINAN DAN K3 (Cluster Only) | P8: Material | Q8: Vendor
A9: 1.2 | B9: Transportasi, Mobilisasi & demobilisasi | C9: ls | E9: 1 | H9: =D9*F9 -> 0 | K9: =D9+E9 -> 1 | L9: =F9+G9 -> 0 | N9: 500003890 | O9: TRANSPORTASI, MOBILISASI DAN DEMOBILISASI | P9: Material | Q9: Vendor
A10: Sub Total Preparation | H10: =SUM(H8:H8) -> 0 | I10: =SUM(I8:I8) -> 0 | J10: =H10+I10 -> 0
A12: 2 | B12: ODN, OSP, Aktivasi, Instalasi, termasuk ATP Civil Work, Integrasi, Testing & Dokumentasi
A13: 2.1 | B13: ODN
A14: A | B14: FO core type SM G.652.D-ADSS (Aerial dan Underground)
B15: FO core type SM G.652.D-ADSS 24 cores | C15: meter | D15: =E16 -> 1276 | H15: =D15*F15 -> 0 | I15: =E15*G15 -> 0 | K15: =D15+E15 -> 1276 | L15: =F15+G15 -> 0 | N15: 200000100 | O15: FO TYPE SM G.652.D-ADSS 24 CORES | P15: Material | Q15: Internal
B16: Instal FO core type SM G.652.D-ADSS 24 cores | C16: meter | E16: =SUM('BoM AE'!C16:C19) -> 1276 | H16: =D16*F16 -> 0 | I16: =E16*G16 -> 0 | K16: =D16+E16 -> 1276 | L16: =F16+G16 -> 0 | N16: 500002050 | O16: INSTAL FO TYPE SM G.652.D-ADSS 24 CORES | P16: Service | Q16: Vendor
B17: FO core type SM G.652.D-ADSS 36 cores | C17: meter | D17: =E18 -> 0 | H17: =D17*F17 -> 0 | I17: =E17*G17 -> 0 | K17: =D17+E17 -> 0 | L17: =F17+G17 -> 0 | N17: 200000975 | O17: FO TYPE SM G.652.D-ADSS 36 CORES | P17: Material | Q17: Internal
B18: Instal FO core type SM G.652.D-ADSS 36 cores | C18: meter | E18: =SUM('BoM AE'!C20:C23) -> 0 | H18: =D18*F18 -> 0 | I18: =E18*G18 -> 0 | K18: =D18+E18 -> 0 | L18: =F18+G18 -> 0 | N18: 500002051 | O18: INSTAL FO TYPE SM G.652.D-ADSS 36 CORES | P18: Service | Q18: Vendor
B19: FO core type SM G.652.D-ADSS 48 cores | C19: meter | D19: =E20 -> 0 | H19: =D19*F19 -> 0 | I19: =E19*G19 -> 0 | K19: =D19+E19 -> 0 | L19: =F19+G19 -> 0 | N19: 200001038 | O19: FO TYPE SM G.652.D-ADSS 48 CORES | P19: Material | Q19: Internal
B20: Instal FO core type SM G.652.D-ADSS 48 cores | C20: meter | E20: =SUM('BoM AE'!C24:C27) -> 0 | H20: =D20*F20 -> 0 | I20: =E20*G20 -> 0 | K20: =D20+E20 -> 0 | L20: =F20+G20 -> 0 | N20: 500002052 | O20: INSTAL FO TYPE SM G.652.D-ADSS 48 CORES | P20: Service | Q20: Vendor
B21: FO core type SM G.652.D-ADSS 72 cores | C21: meter | N21: 200001970 | O21: FO TYPE SM G.652.D-ADSS 72 CORES | P21: Material | Q21: Internal
B22: Instal FO core type SM G.652.D-ADSS 72 cores | C22: meter | N22: 500003410 | O22: INSTAL FO TYPE SM G.652.D-ADSS 72 CORES | P22: Service | Q22: Vendor
B23: FO core type SM G.652.D-ADSS 96 cores | C23: meter | N23: 200001630 | O23: FO TYPE SM G.652.D-ADSS 96 CORES | P23: Material | Q23: Internal
B24: Instal FO core type SM G.652.D-ADSS 96 cores | C24: meter | N24: 500002890 | O24: INSTAL FO TYPE SM G.652.D-ADSS 96 CORES | P24: Service | Q24: Vendor
B25: FO core type SM G.652.D-ADSS 144 cores | C25: meter | H25: =D25*F25 -> 0 | I25: =E25*G25 -> 0 | K25: =D25+E25 -> 0 | L25: =F25+G25 -> 0 | N25: 200001030 | O25: FO TYPE SM G.652.D-ADSS 144 CORES | P25: Material | Q25: Internal
B26: Instal FO core type SM G.652.D-ADSS 144 cores | C26: meter | H26: =D26*F26 -> 0 | I26: =E26*G26 -> 0 | K26: =D26+E26 -> 0 | L26: =F26+G26 -> 0 | N26: 500002088 | O26: INSTAL FO TYPE SM G.652.D-ADSS 144 CORES | P26: Service | Q26: Vendor
B27: FO core type SM G.652.D-ADSS 288 cores | C27: meter | H27: =D27*F27 -> 0 | I27: =E27*G27 -> 0 | K27: =D27+E27 -> 0 | L27: =F27+G27 -> 0 | N27: 200001015 | O27: FO TYPE SM G.652.D-ADSS 288 CORES | P27: Material | Q27: Internal
B28: Instal FO core type SM G.652.D-ADSS 288 cores | C28: meter | H28: =D28*F28 -> 0 | I28: =E28*G28 -> 0 | K28: =D28+E28 -> 0 | L28: =F28+G28 -> 0 | N28: 500002089 | O28: INSTAL FO TYPE SM G.652.D-ADSS 288 CORES | P28: Service | Q28: Vendor
B29: Round Cable 1C - 50 m | C29: set | N29: 200002668 | O29: ROUND CABLE 1C - 50 M | P29: Material
B30: Install Round Cable 1C - 50 m | C30: set | N30: 500004722 | O30: INSTALL ROUND CABLE 1C - 50 M | P30: Service
B31: Round Cable 1C - 100 m | C31: set | N31: 200002669 | O31: ROUND CABLE 1C - 100 M | P31: Material
B32: Install Round Cable 1C - 100 m | C32: set | N32: 500004723 | O32: INSTALL ROUND CABLE 1C - 100 M | P32: Service
B33: Round Cable 1C - 150 m | C33: set | N33: 200002670 | O33: ROUND CABLE 1C - 150 M | P33: Material
B34: Install Round Cable 1C - 150 m | C34: set | N34: 500004724 | O34: INSTALL ROUND CABLE 1C - 150 M | P34: Service
B35: Round Cable 1C - 200 m | C35: set | N35: 200002671 | O35: ROUND CABLE 1C - 200 M | P35: Material
B36: Install Round Cable 1C - 200 m | C36: set | N36: 500004725 | O36: INSTALL ROUND CABLE 1C - 200 M | P36: Service
B37: Round Cable 1C - 250 m | C37: set | N37: 200002713 | O37: ROUND CABLE 1C - 250 M | P37: Material
B38: Install Round Cable 1C - 250 m | C38: set | N38: 500004777 | O38: INSTALL ROUND CABLE 1C - 250 M | P38: Service
B39: Round Cable 1C - 300 m | C39: set | N39: 200002714 | O39: ROUND CABLE 1C - 300 M | P39: Material
B40: Install Round Cable 1C - 300 m | C40: set | N40: 500004778 | O40: INSTALL ROUND CABLE 1C - 300 M | P40: Service
A41: B | B41: Fiber Distribution Terminal (FDT) SC/APC c/w Box, matrix terminal, Patchtray, Pigtail, label & accessories include concrete base | H41: =D41*F41 -> 0 | I41: =E41*G41 -> 0 | K41: =D41+E41 -> 0 | L41: =F41+G41 -> 0
...

Sheet BoQ NRO All Feeder
A1: DISTRIBUSI - SUBFEEEDER | N1: AS PLAN
A2: BOQ GPON FTTH FOR OPTICAL DISTRIBUTION NETWORK (ODN) | N2: OLT Name | O2: XXX
A3: PT. EKA MAS REPUBLIK ODN, OSP, Aktivasi, Instalasi, Integrasi, Testing & Dokumentasi | N3: Cluster | O3: XXX
A4: PROJECT ROLL OUT 2024 | N4: Net Type | O4: Aerial
N5: HP | O5: XXX
A6: No | B6: Description/Item | C6: Unit | D6: Material Qty | E6: Service Qty | F6: Material Price | G6: Service Price | H6: Total Material Price | I6: Total Service Price | J6: Total Price | M6: Koreksi No Material | N6: No Material | O6: Short Text/Description SAP | P6: Remarks | Q6: Service
A7: 1 | B7: Pengamanan & Persiapan
A8: 1.1 | B8: Pengamanan & Persiapan (Kesehatan dan Keselamatan Kerja) | C8: ls | E8: 1 | H8: =#REF!*F8 -> #REF! | K8: =#REF!+D8 -> #REF! | L8: =F8+G8 -> 0 | N8: 500003800 | O8: PENGAMANAN & PERSIAPAN | P8: Material | Q8: Vendor
A9: 1.2 | B9: Transportasi, Mobilisasi & demobilisasi | C9: ls | E9: 1 | H9: =D9*F9 -> 0 | K9: =D9+E9 -> 1 | L9: =F9+G9 -> 0 | N9: 500003890 | O9: TRANSPORTASI, MOBILISASI DAN DEMOBILISASI | P9: Material | Q9: Vendor
A10: Sub Total Preparation | H10: =SUM(H8:H8) -> #REF! | I10: =SUM(I8:I8) -> 0 | J10: =H10+I10 -> #REF!
A12: 2 | B12: ODN, OSP, Aktivasi, Instalasi, termasuk ATP Civil Work, Integrasi, Testing & Dokumentasi
A13: 2.1 | B13: ODN
A14: A | B14: FO core type SM G.652.D-ADSS (Aerial dan Underground)
B15: FO core type SM G.652.D-ADSS 24 cores | C15: meter | D15: =E16 -> 0 | H15: =D15*F15 -> 0 | I15: =E15*G15 -> 0 | K15: =D15+E15 -> 0 | L15: =F15+G15 -> 0 | N15: 200000100 | O15: FO TYPE SM G.652.D-ADSS 24 CORES | P15: Material | Q15: Internal
B16: Instal FO core type SM G.652.D-ADSS 24 cores | C16: meter | E16: =SUM('BoM AE'!J9) -> 0 | H16: =D16*F16 -> 0 | I16: =E16*G16 -> 0 | K16: =D16+E16 -> 0 | L16: =F16+G16 -> 0 | N16: 500002050 | O16: INSTAL FO TYPE SM G.652.D-ADSS 24 CORES | P16: Service | Q16: Vendor
B17: FO core type SM G.652.D-ADSS 36 cores | C17: meter | D17: =E18 -> 0 | H17: =D17*F17 -> 0 | I17: =E17*G17 -> 0 | K17: =D17+E17 -> 0 | L17: =F17+G17 -> 0 | N17: 200000975 | O17: FO TYPE SM G.652.D-ADSS 36 CORES | P17: Material | Q17: Internal
B18: Instal FO core type SM G.652.D-ADSS 36 cores | C18: meter | E18: =SUM('BoM AE'!J10) -> 0 | H18: =D18*F18 -> 0 | I18: =E18*G18 -> 0 | K18: =D18+E18 -> 0 | L18: =F18+G18 -> 0 | N18: 500002051 | O18: INSTAL FO TYPE SM G.652.D-ADSS 36 CORES | P18: Service | Q18: Vendor
B19: FO core type SM G.652.D-ADSS 48 cores | C19: meter | D19: =E20 -> 0 | H19: =D19*F19 -> 0 | I19: =E19*G19 -> 0 | K19: =D19+E19 -> 0 | L19: =F19+G19 -> 0 | N19: 200001038 | O19: FO TYPE SM G.652.D-ADSS 48 CORES | P19: Material | Q19: Internal
B20: Instal FO core type SM G.652.D-ADSS 48 cores | C20: meter | E20: =SUM('BoM AE'!J11) -> 0 | H20: =D20*F20 -> 0 | I20: =E20*G20 -> 0 | K20: =D20+E20 -> 0 | L20: =F20+G20 -> 0 | N20: 500002052 | O20: INSTAL FO TYPE SM G.652.D-ADSS 48 CORES | P20: Service | Q20: Vendor
B21: FO core type SM G.652.D-ADSS 72 cores | C21: meter | D21: =E22 -> 0 | N21: 200001970 | O21: FO TYPE SM G.652.D-ADSS 72 CORES | P21: Material | Q21: Internal
B22: Instal FO core type SM G.652.D-ADSS 72 cores | C22: meter | E22: =SUM('BoM AE'!J12) -> 0 | N22: 500003410 | O22: INSTAL FO TYPE SM G.652.D-ADSS 72 CORES | P22: Service | Q22: Vendor
B23: FO core type SM G.652.D-ADSS 96 cores | C23: meter | D23: =E24 -> 0 | N23: 200001630 | O23: FO TYPE SM G.652.D-ADSS 96 CORES | P23: Material | Q23: Internal
B24: Instal FO core type SM G.652.D-ADSS 96 cores | C24: meter | E24: =SUM('BoM AE'!J13) -> 0 | N24: 500002890 | O24: INSTAL FO TYPE SM G.652.D-ADSS 96 CORES | P24: Service | Q24: Vendor
B25: FO core type SM G.652.D-ADSS 144 cores | C25: meter | D25: =E26 -> 0 | H25: =D25*F25 -> 0 | I25: =E25*G25 -> 0 | K25: =D25+E25 -> 0 | L25: =F25+G25 -> 0 | N25: 200001030 | O25: FO TYPE SM G.652.D-ADSS 144 CORES | P25: Material | Q25: Internal
B26: Instal FO core type SM G.652.D-ADSS 144 cores | C26: meter | E26: =SUM('BoM AE'!J14) -> 0 | H26: =D26*F26 -> 0 | I26: =E26*G26 -> 0 | K26: =D26+E26 -> 0 | L26: =F26+G26 -> 0 | N26: 500002088 | O26: INSTAL FO TYPE SM G.652.D-ADSS 144 CORES | P26: Service | Q26: Vendor
B27: FO core type SM G.652.D-ADSS 288 cores | C27: meter | D27: =E28 -> 0 | H27: =D27*F27 -> 0 | I27: =E27*G27 -> 0 | K27: =D27+E27 -> 0 | L27: =F27+G27 -> 0 | N27: 200001015 | O27: FO TYPE SM G.652.D-ADSS 288 CORES | P27: Material | Q27: Internal
B28: Instal FO core type SM G.652.D-ADSS 288 cores | C28: meter | E28: =SUM('BoM AE'!J15) -> 0 | H28: =D28*F28 -> 0 | I28: =E28*G28 -> 0 | K28: =D28+E28 -> 0 | L28: =F28+G28 -> 0 | N28: 500002089 | O28: INSTAL FO TYPE SM G.652.D-ADSS 288 CORES | P28: Service | Q28: Vendor
B29: Round Cable 1C - 50 m | C29: set | N29: 200002668 | O29: ROUND CABLE 1C - 50 M | P29: Material
B30: Install Round Cable 1C - 50 m | C30: set | N30: 500004722 | O30: INSTALL ROUND CABLE 1C - 50 M | P30: Service
B31: Round Cable 1C - 100 m | C31: set | N31: 200002669 | O31: ROUND CABLE 1C - 100 M | P31: Material
B32: Install Round Cable 1C - 100 m | C32: set | N32: 500004723 | O32: INSTALL ROUND CABLE 1C - 100 M | P32: Service
B33: Round Cable 1C - 150 m | C33: set | N33: 200002670 | O33: ROUND CABLE 1C - 150 M | P33: Material
B34: Install Round Cable 1C - 150 m | C34: set | N34: 500004724 | O34: INSTALL ROUND CABLE 1C - 150 M | P34: Service
B35: Round Cable 1C - 200 m | C35: set | N35: 200002671 | O35: ROUND CABLE 1C - 200 M | P35: Material
B36: Install Round Cable 1C - 200 m | C36: set | N36: 500004725 | O36: INSTALL ROUND CABLE 1C - 200 M | P36: Service
B37: Round Cable 1C - 250 m | C37: set | N37: 200002713 | O37: ROUND CABLE 1C - 250 M | P37: Material
B38: Install Round Cable 1C - 250 m | C38: set | N38: 500004777 | O38: INSTALL ROUND CABLE 1C - 250 M | P38: Service
B39: Round Cable 1C - 300 m | C39: set | N39: 200002714 | O39: ROUND CABLE 1C - 300 M | P39: Material
B40: Install Round Cable 1C - 300 m | C40: set | N40: 500004778 | O40: INSTALL ROUND CABLE 1C - 300 M | P40: Service
A41: B | B41: Fiber Distribution Terminal (FDT) SC/APC c/w Box, matrix terminal, Patchtray, Pigtail, label & accessories include concrete base | H41: =D41*F41 -> 0 | I41: =E41*G41 -> 0 | K41: =D41+E41 -> 0 | L41: =F41+G41 -> 0
...

Sheet BoM AE
A1: BoM Cluster - | B1: ='BoQ NRO Cluster'!O3 -> APD - RANCA PANGGUNG RW 08 | C1: Qty | D1: Unit | E1: Remarks | H1: BoM - Main/Hub/Sub Feeder | I1: ='BoQ NRO All Feeder'!O3 -> XXX | J1: Qty | K1: Units | L1: Remarks
A2: Total Rute | B2: Line A - 24C/2T | C2: 484 | D2: m | E2: qty based on design | H2: Total Route to FDT | I2: 24C/2T | J2: 0 | K2: m | L2: qty based on design
B3: Line B - 24C/2T | C3: 490 | D3: m | E3: qty based on design | I3: 36C/3T | J3: 0 | K3: m | L3: qty based on design
B4: Line C - 24C/2T | C4: 0 | D4: m | E4: qty based on design | I4: 48C/4T | J4: 0 | K4: m | L4: qty based on design
B5: Line D - 24C/2T | C5: 0 | D5: m | E5: qty based on design | I5: 72C/6T | J5: 0 | K5: m | L5: qty based on design
B6: Line A - 36C/3T | C6: 0 | D6: m | E6: qty based on design | I6: 96C/8T | J6: 0 | K6: m | L6: qty based on design
B7: Line B - 36C/3T | C7: 0 | D7: m | E7: qty based on design | I7: 144C/12T | J7: 0 | K7: m | L7: auto based on formula
B8: Line C - 36C/3T | C8: 0 | D8: m | E8: qty based on design | I8: 288C/24T | J8: 0 | K8: m | L8: auto based on formula
B9: Line D - 36C/3T | C9: 0 | D9: m | E9: qty based on design | H9: Total Panjang Kabel to FDT (Slack + toleransi 5%) | I9: =I2 -> 24C/2T | J9: =ROUNDUP(((J2)+(J16*20))*1.05,0) -> 0 | K9: m | L9: auto based on formula
B10: Line A - 48C/4T | C10: 0 | D10: m | E10: qty based on design | I10: =I3 -> 36C/3T | J10: =ROUNDUP(((J3)+(J17*20))*1.05,0) -> 0 | K10: m | L10: auto based on formula
B11: Line B - 48C/4T | C11: 0 | D11: m | E11: qty based on design | I11: =I4 -> 48C/4T | J11: =ROUNDUP(((J4)+(J18*20))*1.05,0) -> 0 | K11: m | L11: auto based on formula
B12: Line C - 48C/4T | C12: 0 | D12: m | E12: qty based on design | I12: 72C/6T | J12: =ROUNDUP(((J5)+(J19*20))*1.05,0) -> 0 | K12: m | L12: auto based on formula
B13: Line D - 48C/4T | C13: 0 | D13: m | E13: qty based on design | I13: 96C/8T | J13: =ROUNDUP(((J6)+(J20*20))*1.05,0) -> 0 | K13: m | L13: auto based on formula
A14: Total Rute | C14: =SUM(C2:C13) -> 974 | D14: m | E14: auto (based on formula) | I14: =I7 -> 144C/12T | J14: =ROUNDUP(((J7)+(J21*20))*1.05,0) -> 0 | K14: m | L14: auto based on formula
B15: Rute Strand Wire | C15: =64+42+41+39 -> 186 | D15: m | E15: qty based on design | I15: =I8 -> 288C/24T | J15: =ROUNDUP(((J8)+(J22*20))*1.05,0) -> 0 | K15: m | L15: auto based on formula
A16: Total Panjang Kabel (Slack + Toleransi 5%) | B16: =B2 -> Line A - 24C/2T | C16: =IF(C2=0,0,(ROUNDUP(((C2)+($C$44+$C$40)*20)*1.05,0))) -> 614 | D16: m | E16: auto (based on formula) | H16: Total Coil / Slack | I16: =I2 -> 24C/2T | J16: =IF(J2=0,0,(ROUNDUP((J2/400)+1,0))) -> 0 | K16: pcs | L16: auto based on formula
B17: =B3 -> Line B - 24C/2T | C17: =IF(C3=0,0,(ROUNDUP(((C3)+($C$45+$C$41)*20)*1.05,0))) -> 662 | D17: m | E17: auto (based on formula) | I17: =I3 -> 36C/3T | J17: =IF(J3=0,0,(ROUNDUP((J3/400)+1,0))) -> 0 | K17: pcs | L17: qty based on design
B18: =B4 -> Line C - 24C/2T | C18: =IF(C4=0,0,(ROUNDUP(((C4)+($C$46+$C$42)*20)*1.05,0))) -> 0 | D18: m | E18: auto (based on formula) | I18: =I4 -> 48C/4T | J18: =IF(J4=0,0,(ROUNDUP((J4/400)+1,0))) -> 0 | K18: pcs | L18: qty based on design
B19: =B5 -> Line D - 24C/2T | C19: =IF(C5=0,0,(ROUNDUP(((C5)+($C$47+$C$43)*20)*1.05,0))) -> 0 | D19: m | E19: auto (based on formula) | I19: 72C/6T | J19: =IF(J5=0,0,(ROUNDUP((J5/400)+1,0))) -> 0 | K19: pcs | L19: qty based on design
B20: =B6 -> Line A - 36C/3T | C20: =IF(C6=0,0,(ROUNDUP(((C6)+($C$44+$C$40)*20)*1.05,0))) -> 0 | D20: m | E20: auto (based on formula) | I20: 96C/8T | J20: =IF(J6=0,0,(ROUNDUP((J6/400)+1,0))) -> 0 | K20: pcs | L20: qty based on design
B21: =B7 -> Line B - 36C/3T | C21: =IF(C7=0,0,(ROUNDUP(((C7)+($C$45+$C$41)*20)*1.05,0))) -> 0 | D21: m | E21: auto (based on formula) | I21: =I7 -> 144C/12T | J21: =IF(J7=0,0,(ROUNDUP((J7/400)+1,0))) -> 0 | K21: pcs | L21: qty based on design
B22: =B8 -> Line C - 36C/3T | C22: =IF(C8=0,0,(ROUNDUP(((C8)+($C$46+$C$42)*20)*1.05,0))) -> 0 | D22: m | E22: auto (based on formula) | I22: =I8 -> 288C/24T | J22: =IF(J8=0,0,(ROUNDUP((J8/400)+1,0))) -> 0 | K22: pcs | L22: qty based on design
B23: =B9 -> Line D - 36C/3T | C23: =IF(C9=0,0,(ROUNDUP(((C9)+($C$47+$C$43)*20)*1.05,0))) -> 0 | D23: m | E23: auto (based on formula) | H23: Closure | I23: Fiber Optic Joint Closure Type In-line 24 Core | J23: 0 | K23: units | L23: qty based on design
B24: =B10 -> Line A - 48C/4T | C24: =IF(C10=0,0,(ROUNDUP(((C10)+($C$44+$C$40)*20)*1.05,0))) -> 0 | D24: m | E24: auto (based on formula) | I24: Fiber Optic Joint Closure Type In-line 36 Core | J24: 0 | K24: units | L24: qty based on design
B25: =B11 -> Line B - 48C/4T | C25: =IF(C11=0,0,(ROUNDUP(((C11)+($C$45+$C$41)*20)*1.05,0))) -> 0 | D25: m | E25: auto (based on formula) | I25: Fiber Optic Joint Closure Type In-line 48 Core | J25: 0 | K25: units | L25: qty based on design
B26: =B12 -> Line C - 48C/4T | C26: =IF(C12=0,0,(ROUNDUP(((C12)+($C$46+$C$42)*20)*1.05,0))) -> 0 | D26: m | E26: auto (based on formula) | I26: Fiber Optic Joint Closure Type In-line 72 Core | J26: 0 | K26: units | L26: qty based on design
B27: =B13 -> Line D - 48C/4T | C27: =IF(C13=0,0,(ROUNDUP(((C13)+($C$47+$C$43)*20)*1.05,0))) -> 0 | D27: m | E27: auto (based on formula) | I27: Fiber Optic Joint Closure Type In-line 96 Core | J27: 0 | K27: units | L27: qty based on design
A28: Total Panjang Cable | C28: =SUM(C16:C27) -> 1276 | D28: m | E28: auto (based on formula) | I28: Fiber Optic Joint Closure Type In-line 144 Core | J28: 0 | K28: units | L28: qty based on design
B29: Panjang Strand Wire + toleransi 5% | C29: =ROUNDUP(((C15*5%)+C15),0) -> 196 | D29: m | E29: auto (based on formula) | I29: Fiber Optic Joint Closure Type In-line 288 Core | J29: 0 | K29: units | L29: qty based on design
A30: Total FDT Pole Mounted | B30: FDT Pole Mounted 48 core | C30: 1 | D30: set | E30: qty based on design | I30: Fiber Optic Joint Closure Type Dome 24 Core | J30: 0 | K30: units | L30: qty based on design
B31: FDT Pole Mounted 72 core | C31: 0 | D31: set | E31: qty based on design | I31: Fiber Optic Joint Closure Type Dome 36 Core | J31: 0 | K31: units | L31: auto based on formula
B32: FDT Pole Mounted 96 core | C32: 0 | D32: set | E32: qty based on design | I32: Fiber Optic Joint Closure Type Dome 48 Core | J32: 0 | K32: units | L32: auto based on formula
B33: FDT Ground Mounted 144 core | C33: 0 | D33: set | E33: qty based on design | I33: Fiber Optic Joint Closure Type Dome 72 Core | J33: 0 | K33: units | L33: auto based on formula
A34: Total Splitter | B34: Modular 1:8 di FDT | C34: =(ROUNDUP((C35/8),0)) -> 2 | D34: unit | E34: auto (based on formula) | I34: Fiber Optic Joint Closure Type Dome 96 Core | J34: 0 | K34: units | L34: auto based on formula
B35: FAT 1:8 | C35: =SUM(C36:C39) -> 10 | D35: unit | E35: auto (based on formula) | I35: Fiber Optic Joint Closure Type Dome 144 Core | J35: 0 | K35: units | L35: auto based on formula
A36: Total FAT | B36: Line A | C36: 4 | D36: unit | E36: qty based on design | I36: Fiber Optic Joint Closure Type Dome 288 Core | J36: 0 | K36: units | L36: auto based on formula
B37: Line B | C37: 6 | D37: unit | E37: qty based on design | H37: Accessoris (1 set every acc) | I37: Cable loop holder/plat strip/Cable hanger | J37: =SUM(J16:J22) -> 0 | K37: pcs | L37: qty based on design
B38: Line C | C38: 0 | D38: unit | E38: qty based on design | I38: 1. Plate belt 20mm | J38: =J37*4 -> 0 | K38: pcs | L38: auto based on formula
B39: Line D | C39: 0 | D39: unit | E39: qty based on design | I39: 2. Suspension clamp | J39: =ROUNDUP((SUM(J49,J52,J53,J54,J55,J58,J59)*20%),0) -> 0 | K39: pcs | L39: auto based on formula
A40: Total Slack di FDT | B40: =B36 -> Line A | C40: =IF(C36>=1,1,0) -> 1 | D40: slack | E40: auto (based on formula) | I40: 3. Buldog grip | J40: =(J48/40)*6 -> 0 | K40: pcs | L40: qty based on design
...

Sheet CALCULATOR
A1: Type | B1: Percentage | C1: Result
A2: Vendor Name | C2: YOFC International Indonesia | D2: ← Select Dropdown List
A3: Permit | C3: 25000000 | F3: 0.9735
A4: PPh | B4: =VLOOKUP(C2,'[1]Vendor List'!A2:B100,2,0) -> 0.0265 | C4: =INT(C3/(1-B4)) -> 25680534 | E4: =C4*B4 -> 680534.15 | F4: 1
A5: Management Fee | B5: 0 | C5: =C3*B5 -> 0 | E5: =C3+E4 -> 25680534
A6: Total | C6: =C4+C5 -> 25680534
